model
name = main
revision = 10
size = 128 4 30
scale = 0.0078125 0.1 0.0078125
rotation = 90 0 0
origin = +z
shell = Outline 0.25
material lighting = both, roughness = 0.5, fade = true, deform = 10 1, clamp = y
  colors = A:#EEE C:#000 D:#CCC B:#AAA H:#444 G:#666 F:#222 E:#888 K:#48E O:#28E U:#04C Q:#26E I:#446 L:#26C R:#04E S:#224 M:#026 N:#46C V:#226 J:#48C T:#06E P:#06C
material type = basic, lighting = smooth, roughness = 0, refractionRatio = 1, side = back
  colors = Outline:#000
voxels
128-128A19-C364-3(128A16-2C-C21-4C339-)35AB2CD89A16-2C4-23C2-17C86-21C4-6C203-35AB2CD89A16-2C4-23C2-C15-C86-21C213-3(35AB2CD89A17-2C22-4C2-C15-C320-)27A3D5AB2CDA3D8A4D9A3D8A3D10A4D7A3D8A3D15A17-2C22-4C18-C320-5AECF4AGFE3AD2CB3AE4CHD3AB2CEH3CFB4ADH4CHD2AHC2EF3CGD4AEF4CG6ABF4CH4AG4CHD4AG4CFB13A17-2C22-4C18-C320-5AB2CD3A2CF3AB2CD2AH2C2F3CD2AB4C2F3CB3AFCF2EHCD2AH4C2F2CFD3A3CF3CE4AE3C4F3AH2C2F2CFD2AG2CGEGCE13A17-2C24-2C18-C320-6A2CB2AB3CD2AECH2AE2CE2ADFCH2AB3CB2ADF2C2AB2CD3ABD2AH2CHD2AE2CG3AGD2ADFCF3AB2CHD3AD2AG2CB2AB2CG2A2CE3ADB13A17-2C24-2C18-C320-6AGCG2AG3CB2AFCE2AFCH4AE2CDAB2CE4AB2CBAB2CB7AH2CD4AH2C8AE2CD2AH2CD6AD2CG4AGCF2A2CG18A17-2C44-C320-6ABCF2AFCBCGAD2CDAD2CH4BG2CDAB2CD5A2CG2AF2CED5AHCH5AB2CD4ADEGH2CD2A2CG7AB2CG4BG2CDAG2CGD16A17-2C44-C320-6AD2C2DCGA2FABCF2AB10CDAB2C6AFCH2ADF3CGD3AHCG5AB2CB2ABF6CDAD2CE7AB10CD2AG3CHB5AE2GD5A17-2C44-C320-7AFC2BCBAGCDECG2AD2CE7D2AB2C6AFCG4ABH3CD2AHCG5AB2CBAE2CHDAB2CDAD2CE7AB2CE7D4ADG3CE3AIJKLMD4A63-C320-7AEC2GCDABCEFCB2AD2CG9AB2CD4AD2CE6AB2CG2AHCF5AE2CDA2CH3AB2CD2AFCF7AD2CE13ADH2C2AEN2KOPI4A63-C320-7AD3CH3AF3C4AG2CB8AB2CG4AG2CD7AHCF2AH2CB3ADFCFAD2CG3AB2CD2AE2CE7AH2CD13AB2CDAGKO2QRS4A63-C320-8A3CB3AG2CH4AD3CG3B2G2AB3CH2BG2CH2ABHB2DB2CG2AH3CE2BH2CB2AFCFBDBF2CGDADF2CG2BEH2AD3CE3BHE2AFE3DHCF2AELOQTUH4A63-C320-8AG2CD3AB2CE5ADF6CG2AB2CF5CHD2AB6CFD2AH8CE3AE5CGF2CE2ADF6C3ABF6CE2A7CB2ADVURUMB4A63-C320-8AD2E5A2ED7ABG2HGB3AD2EDBGHGB5ABE2HGE4AHCHDE2HGD5ABGHGDADGHB4ABG2HGB5ABG2HGB3ADEG2HED4ADGSHB5A3(63-C320-59AHCH66A)2(384-59AHCH66A)384-59ADBD66A2(384-128A)256-
